Workbook
Name PP: o!$O$4:$O$63

Sheet נתונים גולמיים שאלון התנהגות
P1: =COLUMN(A2) -> 1 | Q1: =COLUMN(B2) -> 2 | R1: =COLUMN(C2) -> 3 | S1: =COLUMN(D2) -> 4 | T1: =COLUMN(E2) -> 5 | U1: =COLUMN(F2) -> 6 | V1: =COLUMN(G2) -> 7 | W1: =COLUMN(H2) -> 8 | ... BW1: =COLUMN(BH2) -> 60
A2: What is your Prolific ID? Please note that this response should auto-fill with the correct ID | C2: Start Date | D2: End Date | E2: IP Address | F2: Progress | G2: Duration (in seconds) | H2: Finished | I2: Recorded Date | J2: Response ID | K2: Location Latitude | L2: Location Longitude | M2: Distribution Channel | N2: Imagine you were in a social gathering with your childhood friends. Write a hypothetical social media post about this event. | O2: Your significant other is having a birthday. Write them a social media post that congratulates them. | P2: I accept people the way they are. | Q2: I believe in the importance of art. | R2: My moods change easily. | S2: I take care of other people before taking care of myself. | T2: I am always prepared. | U2: I have a vivid imagination. | V2: I feel comfortable around people. | W2: I often feel blue. | X2: I am the life of the party. | Y2: I treat everyone with kindness and sympathy. | Z2: I get chores done right away. | AA2: I have a kind word for everyone. | AB2: I am skilled in handling social situations. | AC2: I often feel anxious about what could go wrong. | AD2: I start arguments just for the fun of it. | AE2: I often worry that I am not good enough. | AF2: I find it difficult to get to work. | AG2: I stay in the background. | AH2: There are many things that I do not like about myself. | AI2: I seldom feel blue. | AJ2: I do not like art. | AK2: I stop what I am doing to help other people. | AL2: I change my plans frequently. | AM2: I am often troubled by negative thoughts. | AN2: I feel comfortable with myself. | AO2: I avoid philosophical discussions. | AP2: Original | AQ2: Systematic | AR2: Shy | AS2: Soft-Hearted | AT2: Tense | AU2: Inquisitive | AV2: Forgetful | AW2: Reserved | AX2: Agreeable | AY2: Nervous | AZ2: Creative | BA2: Self-Disciplined | BB2: Outgoing | BC2: Charitable | BD2: Moody | BE2: Imaginative | BF2: Organized | BG2: Talkative | BH2: Humble | BI2: Pessimistic | BJ2: I have a lot to say. | BK2: I enjoy going to art museums. | BL2: I always make good use of my time. | BM2: I am interested in the meaning of things. | BN2: I avoid taking on a lot of responsibility. | BO2: I don't like to draw attention to myself. | BP2: I feel I am better than other people. | BQ2: I make friends easily. | BR2: I make plans and stick to them. | BS2: I am not interested in abstract ideas. | BT2: I criticize other people. | BU2: I don't talk a lot. | BV2: I enjoy hearing new ideas. | BW2: It’s important to me that people are on time. | BX2: PROLIFIC_PID | BY2: Create New Field or Choose From Dropdown... | BZ2: Q2.3 - Actionability | CA2: Q2.3 - Effort | CB2: Q2.3 - Effort Numeric | CC2: Q2.3 - Emotion Intensity | CD2: Q2.3 - Emotion | CE2: Q2.3 - Parent Topics | CF2: Q2.3 - Sentiment Polarity | CG2: Q2.3 - Sentiment Score | CH2: Q2.3 - Sentiment | CI2: Q2.3 - Topic Sentiment Label | CJ2: Q2.3 - Topic Sentiment Score | CK2: Q2.3 - Topics | CL2: Q_AmbiguousTextPresent | CM2: Q_AmbiguousTextQuestions | CN2: Q2.3 - Topic Hierarchy Level 1
A3: 66f4147ffea1a6689de3a7ac | B3: ="p"&ROW(A1) -> p1 | C3: 45574.861 | D3: 45574.87 | E3: 185.100.169.179 | F3: 100 | G3: 754 | H3: True | I3: 45574.87 | J3: R_2XrDc7sxdHaRNmx | K3: 51.5074 | L3: -0.1196 | M3: anonymous | N3: Hey guys!!! guess who we have here today??? My childhood friends came over. Oh my God, i have really missed them, i saw them last about 8 years ago but we've always been in communication. I'm so happy to see them and i can't wait to update you guys on the plans we have to catch up. Stay tuned! | O3: Happy birthday to the love of my life. I can't imagine what my life could have been without you, you brought colors into my life. On this big day of yours, i wish you heavens choicest blessings and i pray all your hear desires are granted. I love you so much and i hope i make you happy as much as you make me | P3: 4 | Q3: 5 | R3: 5 | S3: 2 | T3: 4 | U3: 4 | V3: 2 | W3: 3 | X3: 2 | Y3: 4 | Z3: 3 | AA3: 4 | AB3: 3 | AC3: 5 | AD3: 2 | AE3: 3 | AF3: 2 | AG3: 4 | AH3: 3 | AI3: 1 | AJ3: 1 | AK3: 3 | AL3: 3 | AM3: 4 | AN3: 4 | AO3: 3 | AP3: 3 | AQ3: 3 | AR3: 5 | AS3: 5 | AT3: 5 | AU3: 4 | AV3: 4 | AW3: 5 | AX3: 4 | AY3: 5 | AZ3: 4 | BA3: 5 | BB3: 2 | BC3: 5 | BD3: 4 | BE3: 4 | BF3: 5 | BG3: 2 | BH3: 5 | BI3: 3 | BJ3: 3 | BK3: 5 | BL3: 4 | BM3: 5 | BN3: 3 | BO3: 3 | BP3: 2 | BQ3: 5 | BR3: 5 | BS3: 1 | BT3: 1 | BU3: 1 | BV3: 5 | BW3: 5 | BX3: 66f4147ffea1a6689de3a7ac | BZ3: other | CA3: Neutral | CB3: 0 | CC3: High | CD3: Mixed | CF3: 0 | CG3: 2 | CH3: Very Positive | CK3: Unknown | CL3: 1 | CM3: QID84
A4: 5dc5ab2bd9873541c1569918 | B4: ="p"&ROW(A2) -> p2 | C4: 45574.861 | D4: 45574.872 | E4: 82.132.228.139 | F4: 100 | G4: 961 | H4: True | I4: 45574.872 | J4: R_2aaGfg9BUytDOPV | K4: 51.4897 | L4: -0.1063 | M4: anonymous | N4: Wow. Having a great time catching up with old childhood friends after over 50 years! We haven't changed a bit 😉😂. Other than having several marriages, 18 children and 7 grandchildren between us. Life has definitely been a journey and pretty good to all of us 🥰. Lets not leave it another 50 years to catch up ❤❤ | O4: Happy Birthday to this amazing man who I'm so proud to call my husband and father of my chidren. Hope you have an absolutely brilliant day and so glad i get to share it with you. You're definitely like a fine wine and get better and better with each passing year. All my love forever and always ❤ | P4: 4 | Q4: 5 | R4: 5 | S4: 5 | T4: 1 | U4: 5 | V4: 3 | W4: 4 | X4: 3 | Y4: 4 | Z4: 2 | AA4: 4 | AB4: 4 | AC4: 4 | AD4: 1 | AE4: 5 | AF4: 3 | AG4: 3 | AH4: 4 | AI4: 1 | AJ4: 1 | AK4: 4 | AL4: 5 | AM4: 4 | AN4: 2 | AO4: 1 | AP4: 3 | AQ4: 4 | AR4: 2 | AS4: 5 | AT4: 4 | AU4: 5 | AV4: 5 | AW4: 3 | AX4: 4 | AY4: 3 | AZ4: 4 | BA4: 2 | BB4: 3 | BC4: 3 | BD4: 4 | BE4: 5 | BF4: 2 | BG4: 4 | BH4: 4 | BI4: 2 | BJ4: 4 | BK4: 4 | BL4: 2 | BM4: 5 | BN4: 2 | BO4: 3 | BP4: 1 | BQ4: 3 | BR4: 1 | BS4: 1 | BT4: 1 | BU4: 2 | BV4: 5 | BW4: 3 | BX4: 5dc5ab2bd9873541c1569918 | BZ4: other | CA4: Easy | CB4: 1 | CC4: High | CD4: Love,Trust,Joy | CF4: 0 | CG4: 2 | CH4: Very Positive | CK4: Unknown | CL4: 1 | CM4: QID84
A5: 6139bb7008f1e7f556c8b7d2 | B5: ="p"&ROW(A3) -> p3 | C5: 45574.861 | D5: 45574.873 | E5: 176.26.166.121 | F5: 100 | G5: 1040 | H5: True | I5: 45574.873 | J5: R_2ANjwvD8lOgoDlN | K5: 52.9029 | L5: -1.5046 | M5: anonymous | N5: An unforgettable day with childhood friends! A magical day reminicising together and catching up after so long. Doesn’t matter how long it’s been we all slot back together like no time has passed at all. Watching our kids play together and seeing the cycles of life begin all over again is so emotional. Love you all xx #westhillgang #pyegreenmassive #childhood #friends | O5: Happy Birthday to my best friend, the best husband and dad in the world! I’ve celebrated 13 of your birthdays with you and every day in between and for all the chats and hugs, the love, the tough times, it is never ever enough. I look forward to seeing you every morning, I can’t wait to see you after work every day. The love of my life, I am so in love with you. Happy Birthday, my love xxx | P5: 4 | Q5: 5 | R5: 2 | S5: 5 | T5: 3 | U5: 2 | V5: 1 | W5: 5 | X5: 1 | Y5: 4 | Z5: 4 | AA5: 3 | AB5: 1 | AC5: 5 | AD5: 1 | AE5: 5 | AF5: 4 | AG5: 4 | AH5: 5 | AI5: 1 | AJ5: 1 | AK5: 5 | AL5: 2 | AM5: 5 | AN5: 1 | AO5: 1 | AP5: 3 | AQ5: 3 | AR5: 4 | AS5: 5 | AT5: 5 | AU5: 4 | AV5: 2 | AW5: 4 | AX5: 3 | AY5: 5 | AZ5: 4 | BA5: 1 | BB5: 1 | BC5: 5 | BD5: 2 | BE5: 4 | BF5: 5 | BG5: 3 | BH5: 4 | BI5: 2 | BJ5: 4 | BK5: 5 | BL5: 2 | BM5: 4 | BN5: 2 | BO5: 5 | BP5: 2 | BQ5: 1 | BR5: 3 | BS5: 2 | BT5: 3 | BU5: 5 | BV5: 3 | BW5: 2 | BX5: 6139bb7008f1e7f556c8b7d2 | BZ5: other | CA5: Neutral | CB5: 0 | CC5: High | CD5: Joy,Love | CF5: 0 | CG5: 2 | CH5: Very Positive | CK5: Unknown | CL5: 1 | CM5: QID84
A6: 62df57db36c1085c48f8d86c | B6: ="p"&ROW(A4) -> p4 | C6: 45574.862 | D6: 45574.869 | E6: 212.233.148.243 | F6: 100 | G6: 624 | H6: True | I6: 45574.869 | J6: R_8gbyTr0pUTngfFm | K6: 43.4126 | L6: 24.6089 | M6: anonymous | N6: time flies by, I cant believe its been so long since we all met, had so much fun seeing you all again and catching up. I remember when we used to go out on our bikes for hours now we all have our own house's. its crazy. we should make this an annual thing every year. none of you have changed! | O6: Happpy Birthdayyyy. I hope your day is filled with all the things you love and your favorite people. This last year has been amazing and i cant wait to celebrate every birthday with you, even when we are old we'll still have each others company. Love you and cant wait to celebrate this day with you. | P6: 3 | Q6: 4 | R6: 4 | S6: 1 | T6: 1 | U6: 5 | V6: 3 | W6: 3 | X6: 3 | Y6: 4 | Z6: 1 | AA6: 1 | AB6: 2 | AC6: 5 | AD6: 1 | AE6: 4 | AF6: 2 | AG6: 3 | AH6: 5 | AI6: 3 | AJ6: 1 | AK6: 2 | AL6: 4 | AM6: 4 | AN6: 3 | AO6: 1 | AP6: 3 | AQ6: 4 | AR6: 4 | AS6: 3 | AT6: 4 | AU6: 5 | AV6: 3 | AW6: 3 | AX6: 4 | AY6: 4 | AZ6: 4 | BA6: 1 | BB6: 3 | BC6: 1 | BD6: 3 | BE6: 5 | BF6: 1 | BG6: 3 | BH6: 2 | BI6: 1 | BJ6: 3 | BK6: 1 | BL6: 1 | BM6: 4 | BN6: 3 | BO6: 5 | BP6: 1 | BQ6: 3 | BR6: 1 | BS6: 1 | BT6: 2 | BU6: 2 | BV6: 5 | BW6: 2 | BX6: 62df57db36c1085c48f8d86c | BZ6: other | CA6: Neutral | CB6: 0 | CC6: High | CD6: Love | CF6: 0 | CG6: 2 | CH6: Very Positive | CK6: Unknown | CL6: 1 | CM6: QID84
A7: 5de401d34c451d000a669419 | B7: ="p"&ROW(A5) -> p5 | C7: 45574.862 | D7: 45574.869 | E7: 131.227.165.164 | F7: 100 | G7: 628 | H7: True | I7: 45574.869 | J7: R_2FwvrUqmtPGBfia | K7: 51.025 | L7: -0.2978 | M7: anonymous | N7: Day 1s! We finally met up after so long - It was so lovely to catch up with all of you. It has been way too long since we last saw each other, and it really good to hear that you're all doing well. So much has changed since we used to see each other daily, but somehow it feels like no time has passed when we got back togehter Let me know when you're all back in town - we can hang out again. | O7: Happy birthday!! I hope you had an amazing day with friends and family - and thank you for letting me share it with you. I'm so proud of all you've achieved this past year. It has been full of many great times and I'm sure the next year will be full of lots of new opportunities. I look forward to spending the next year with you See you later today! | P7: 5 | Q7: 5 | R7: 4 | S7: 4 | T7: 2 | U7: 5 | V7: 2 | W7: 4 | X7: 2 | Y7: 4 | Z7: 1 | AA7: 3 | AB7: 2 | AC7: 4 | AD7: 1 | AE7: 5 | AF7: 5 | AG7: 2 | AH7: 4 | AI7: 1 | AJ7: 1 | AK7: 4 | AL7: 4 | AM7: 4 | AN7: 3 | AO7: 1 | AP7: 3 | AQ7: 2 | AR7: 4 | AS7: 4 | AT7: 5 | AU7: 4 | AV7: 4 | AW7: 2 | AX7: 4 | AY7: 5 | AZ7: 5 | BA7: 2 | BB7: 2 | BC7: 3 | BD7: 4 | BE7: 5 | BF7: 1 | BG7: 3 | BH7: 3 | BI7: 3 | BJ7: 4 | BK7: 5 | BL7: 2 | BM7: 5 | BN7: 2 | BO7: 3 | BP7: 3 | BQ7: 2 | BR7: 4 | BS7: 1 | BT7: 3 | BU7: 1 | BV7: 5 | BW7: 2 | BX7: 5de401d34c451d000a669419 | BZ7: other | CA7: Neutral | CB7: 0 | CC7: High | CD7: Love | CF7: 0 | CG7: 2 | CH7: Very Positive | CK7: Unknown | CL7: 1 | CM7: QID84
A8: 577e3a5025cb71000128727e | B8: ="p"&ROW(A6) -> p6 | C8: 45574.862 | D8: 45574.87 | E8: 86.174.176.63 | F8: 100 | G8: 718 | H8: True | I8: 45574.87 | J8: R_2EZrcIuHvrRO1G9 | K8: 56.3799 | L8: -3.8194 | M8: anonymous | N8: went to a great birthday party today at the drummond park animal experience centre with ash, jen, jodie jake, alex and all the rest of the crew. loved watching the monkeys antics. the lion cubs were so cute. alex ate too much cake and looked alittle green jake punched him in the stomach to sicee if he could make him sick .. | O8: wow! another landmark birthday. we are all so looking forward to your birthday bash at Fisher's restaurant. can't believe you've come this far despite all the hoops you've had to jump through in the past few years, what an achievement well done you. I know you said no presents but well suspect there may still be one or two surprises | P8: 4 | Q8: 4 | R8: 2 | S8: 3 | T8: 3 | U8: 4 | V8: 2 | W8: 2 | X8: 1 | Y8: 3 | Z8: 3 | AA8: 3 | AB8: 2 | AC8: 2 | AD8: 2 | AE8: 3 | AF8: 3 | AG8: 3 | AH8: 4 | AI8: 4 | AJ8: 2 | AK8: 4 | AL8: 4 | AM8: 3 | AN8: 3 | AO8: 3 | AP8: 4 | AQ8: 3 | AR8: 4 | AS8: 2 | AT8: 2 | AU8: 4 | AV8: 2 | AW8: 4 | AX8: 4 | AY8: 3 | AZ8: 4 | BA8: 2 | BB8: 2 | BC8: 4 | BD8: 1 | BE8: 4 | BF8: 3 | BG8: 3 | BH8: 3 | BI8: 1 | BJ8: 3 | BK8: 4 | BL8: 3 | BM8: 4 | BN8: 3 | BO8: 2 | BP8: 3 | BQ8: 4 | BR8: 3 | BS8: 2 | BT8: 3 | BU8: 3 | BV8: 4 | BW8: 3 | BX8: 577e3a5025cb71000128727e | BZ8: other | CA8: Neutral | CB8: 0 | CC8: Medium | CD8: Mixed | CF8: 0 | CG8: 0 | CH8: Mixed | CK8: Unknown | CL8: 1 | CM8: QID84
A9: 6136001fcd0e07e6f5f66bc1 | B9: ="p"&ROW(A7) -> p7 | C9: 45574.862 | D9: 45574.868 | E9: 86.138.71.199 | F9: 100 | G9: 543 | H9: True | I9: 45574.868 | J9: R_246V0WrsskF7Xwd | K9: 51.6011 | L9: -3.2744 | M9: anonymous | N9: We spent the evening around my house, me and my 4 friends. We love spending time together and chilling out. Once they came here we spent the evening wining and dining. I must stay i think i out done myself with the cooking autumn soup with homemade bread for starters, steak and sides for main and sticky toffee pudding for dessert. Alongside we drank many bottes of wine and had many shots. Feeling it today haha! | O9: Happy birthday, hope you have the best day ever XX I cherish all our memories together and enjoyed our 6 year relationship every day is a blessing spending it with you. Love you forever and always xx Your the most and gentle person ever and make me the happiest girl alive. The love you give me is the best | P9: 3 | Q9: 2 | R9: 4 | S9: 3 | T9: 4 | U9: 4 | V9: 4 | W9: 3 | X9: 2 | Y9: 3 | Z9: 3 | AA9: 2 | AB9: 2 | AC9: 4 | AD9: 2 | AE9: 3 | AF9: 2 | AG9: 3 | AH9: 3 | AI9: 3 | AJ9: 2 | AK9: 3 | AL9: 3 | AM9: 2 | AN9: 3 | AO9: 2 | AP9: 2 | AQ9: 2 | AR9: 2 | AS9: 3 | AT9: 3 | AU9: 2 | AV9: 3 | AW9: 3 | AX9: 2 | AY9: 3 | AZ9: 2 | BA9: 3 | BB9: 3 | BC9: 3 | BD9: 3 | BE9: 3 | BF9: 3 | BG9: 3 | BH9: 2 | BI9: 2 | BJ9: 3 | BK9: 2 | BL9: 3 | BM9: 3 | BN9: 2 | BO9: 3 | BP9: 3 | BQ9: 3 | BR9: 3 | BS9: 4 | BT9: 3 | BU9: 1 | BV9: 3 | BW9: 4 | BX9: 6136001fcd0e07e6f5f66bc1 | BZ9: other | CA9: Neutral | CB9: 0 | CC9: High | CD9: Love | CF9: 0 | CG9: 2 | CH9: Very Positive | CK9: Unknown | CL9: 1 | CM9: QID84
A10: 6658c5cc20f33b713aa2592d | B10: ="p"&ROW(A8) -> p8 | C10: 45574.862 | D10: 45574.868 | E10: 83.105.255.162 | F10: 100 | G10: 552 | H10: True | I10: 45574.868 | J10: R_8oupQGgEZbRq82D | K10: 53.7981 | L10: -1.7623 | M10: anonymous | N10: Lovely to catch up with some old friends and reminisce on childhood memories! It's crazy to see how much everybody has grown and achieved in life and where their paths have taken them. I love days like these, hope to catch up with you all again sometime soon and make more brilliant memories ❤️ | O10: To the love of my life, I hope you have the best day and make the best memories! Thank you for making the world a happier place and staying by my side. I'd be lost without you, don't ever change! I love you with all of my heart, always ❤️ happy birthday my love, here is to many more together xxx | P10: 4 | Q10: 3 | R10: 4 | S10: 4 | T10: 2 | U10: 3 | V10: 2 | W10: 4 | X10: 2 | Y10: 4 | Z10: 2 | AA10: 4 | AB10: 2 | AC10: 5 | AD10: 1 | AE10: 5 | AF10: 3 | AG10: 4 | AH10: 5 | AI10: 2 | AJ10: 4 | AK10: 4 | AL10: 4 | AM10: 5 | AN10: 2 | AO10: 3 | AP10: 3 | AQ10: 3 | AR10: 4 | AS10: 4 | AT10: 4 | AU10: 4 | AV10: 4 | AW10: 4 | AX10: 3 | AY10: 4 | AZ10: 2 | BA10: 3 | BB10: 4 | BC10: 4 | BD10: 3 | BE10: 2 | BF10: 2 | BG10: 3 | BH10: 3 | BI10: 3 | BJ10: 3 | BK10: 2 | BL10: 2 | BM10: 4 | BN10: 4 | BO10: 4 | BP10: 1 | BQ10: 2 | BR10: 2 | BS10: 3 | BT10: 2 | BU10: 3 | BV10: 3 | BW10: 3 | BX10: 6658c5cc20f33b713aa2592d | BZ10: other | CA10: Neutral | CB10: 0 | CC10: High | CD10: Love,Joy | CF10: 0 | CG10: 2 | CH10: Very Positive | CK10: Unknown | CL10: 1 | CM10: QID84
A11: 667ac1826ce22f03fab354c3 | B11: ="p"&ROW(A9) -> p9 | C11: 45574.862 | D11: 45574.874 | E11: 91.124.134.74 | F11: 100 | G11: 1024 | H11: True | I11: 45574.874 | J11: R_7QM2JKoB9kuvsjX | K11: 37.751 | L11: -97.822 | M11: anonymous | N11: Had the best time ca tching up with my chilidhood friends last night! It’s amazing how, despite t he years, we fall riight back into those silly jokes and shared memories. From playing games in the backyard to reminis cing about our wild adventures, it was a great reminder of the b onds that shaped us | O11: Happy Birtihday to the love of my life! i’m so grateful for every moment we share together. You bring so mucih joy and laughter into my world. I can’t wait to celebrate you today and make more amazinng memories! Here’s to another year of love, adventure, and all your dreams coming true. You deserve the best! | P11: 5 | Q11: 5 | R11: 4 | S11: 5 | T11: 5 | U11: 5 | V11: 4 | W11: 1 | X11: 5 | Y11: 5 | Z11: 4 | AA11: 5 | AB11: 5 | AC11: 5 | AD11: 1 | AE11: 1 | AF11: 1 | AG11: 5 | AH11: 1 | AI11: 1 | AJ11: 1 | AK11: 5 | AL11: 3 | AM11: 1 | AN11: 4 | AO11: 4 | AP11: 5 | AQ11: 4 | AR11: 1 | AS11: 5 | AT11: 5 | AU11: 2 | AV11: 5 | AW11: 5 | AX11: 4 | AY11: 1 | AZ11: 5 | BA11: 5 | BB11: 4 | BC11: 5 | BD11: 1 | BE11: 5 | BF11: 5 | BG11: 1 | BH11: 5 | BI11: 1 | BJ11: 5 | BK11: 4 | BL11: 5 | BM11: 5 | BN11: 5 | BO11: 1 | BP11: 5 | BQ11: 5 | BR11: 4 | BS11: 1 | BT11: 5 | BU11: 1 | BV11: 5 | BW11: 5 | BX11: 667ac1826ce22f03fab354c3 | BZ11: other | CA11: Neutral | CB11: 0 | CC11: High | CD11: Love,Thankfulness | CF11: 0 | CG11: 2 | CH11: Very Positive | CK11: Unknown | CL11: 1 | CM11: QID84
A12: 6416533bd4ee6639c3df6040 | B12: ="p"&ROW(A10) -> p10 | C12: 45574.862 | D12: 45574.87 | E12: 5.151.156.70 | F12: 100 | G12: 690 | H12: True | I12: 45574.87 | J12: R_2QyiNkRK3qqULav | K12: 51.4032 | L12: -0.9207 | M12: anonymous | N12: Just got back from a reunion with some friends from back home! These guys always had my back, except when it comes to telling me I'm any good at bowling or mini golf :0 Then again, the drinks probably messed my aim up a litttle bit. Hope to see you guys soon!! Keep it real @xComedyCheesex @Crazygamer05 @7evenup | O12: To this beautiful girl who was a stranger up until 10 months ago, happy birthday my love, I hope that we can spend many more together! P.S. Don't tell anyone I forgot the cake and had to ask you to bake us another one to save myself from the embarassment. Love you lots! Have the best birthday ever &lt;3 | P12: 5 | Q12: 5 | R12: 4 | S12: 4 | T12: 3 | U12: 4 | V12: 5 | W12: 4 | X12: 4 | Y12: 4 | Z12: 2 | AA12: 3 | AB12: 4 | AC12: 3 | AD12: 1 | AE12: 4 | AF12: 3 | AG12: 1 | AH12: 2 | AI12: 2 | AJ12: 1 | AK12: 2 | AL12: 3 | AM12: 2 | AN12: 3 | AO12: 1 | AP12: 5 | AQ12: 4 | AR12: 1 | AS12: 3 | AT12: 2 | AU12: 4 | AV12: 4 | AW12: 4 | AX12: 4 | AY12: 2 | AZ12: 5 | BA12: 3 | BB12: 5 | BC12: 2 | BD12: 2 | BE12: 5 | BF12: 4 | BG12: 4 | BH12: 4 | BI12: 2 | BJ12: 4 | BK12: 4 | BL12: 2 | BM12: 5 | BN12: 2 | BO12: 1 | BP12: 3 | BQ12: 3 | BR12: 3 | BS12: 1 | BT12: 3 | BU12: 2 | BV12: 5 | BW12: 4 | BX12: 6416533bd4ee6639c3df6040 | BZ12: other | CA12: Hard | CB12: -1 | CC12: High | CD12: Mixed | CF12: 0 | CG12: 2 | CH12: Very Positive | CK12: Unknown | CL12: 1 | CM12: QID84
A13: 5966f6c744b2d20001defeec | B13: ="p"&ROW(A11) -> p11 | C13: 45574.862 | D13: 45574.867 | E13: 86.12.79.252 | F13: 100 | G13: 444 | H13: True | I13: 45574.867 | J13: R_2hDvhnUkmz4tRoU | K13: 51.8659 | L13: -2.2059 | M13: anonymous | N13: Such a great night with this incredible bunch, but I'm feeling it this morning! Everyone needs those friends who know you so well, who'll see you through anything and everything. And no matter how old we get are still up for a good girls night out, even if it now takes us two days to recover! Night at Sixways is always the best, love this place, and Love you all 😘😘 | O13: It's official, he's getting older! Happy birthday to my gorgeous husband, another year old and not any wiser! The kindest, funniest soul I will ever meet, and the most amazing dog Dad you could ever find. Looking forward to spoiling you rotten today - and maybe a few surprises this weekend! Happy birthday favourite human xoxo | P13: 5 | Q13: 4 | R13: 3 | S13: 5 | T13: 4 | U13: 4 | V13: 5 | W13: 2 | X13: 4 | Y13: 4 | Z13: 3 | AA13: 4 | AB13: 5 | AC13: 2 | AD13: 1 | AE13: 4 | AF13: 2 | AG13: 1 | AH13: 4 | AI13: 4 | AJ13: 1 | AK13: 4 | AL13: 2 | AM13: 2 | AN13: 4 | AO13: 1 | AP13: 4 | AQ13: 3 | AR13: 2 | AS13: 4 | AT13: 2 | AU13: 5 | AV13: 3 | AW13: 1 | AX13: 4 | AY13: 1 | AZ13: 3 | BA13: 4 | BB13: 5 | BC13: 4 | BD13: 1 | BE13: 4 | BF13: 4 | BG13: 5 | BH13: 3 | BI13: 2 | BJ13: 5 | BK13: 5 | BL13: 4 | BM13: 5 | BN13: 2 | BO13: 1 | BP13: 3 | BQ13: 5 | BR13: 4 | BS13: 1 | BT13: 1 | BU13: 1 | BV13: 4 | BW13: 3 | BX13: 5966f6c744b2d20001defeec | BZ13: other | CA13: Neutral | CB13: 0 | CC13: High | CD13: Mixed | CF13: 0 | CG13: 2 | CH13: Very Positive | CK13: Unknown | CL13: 1 | CM13: QID84
A14: 66c46c4e8a82f52621c06c4f | B14: ="p"&ROW(A12) -> p12 | C14: 45574.862 | D14: 45574.869 | E14: 92.18.162.175 | F14: 100 | G14: 643 | H14: True | I14: 45574.869 | J14: R_2QEFierITmTW23L | K14: 54.9001 | L14: -1.4211 | M14: anonymous | N14: having a brill time at the reunion, saw lots of faces i've not seen in a longggggg time. we mustn't leave it so long next time. just waiting for the karaoke to begin so i can impress everyone with a bit of Enrique ! I hope everyone doesn't leave the room when I start singing otherwise i'll never dare pick up a microphone ever again. Talking about old times at school was a blast....rekindled many good memories. | O14: Happy Birthday to Khaleesy ! Hope you liked the flowers babe, I'll see you when I get home ....expect the princess treatment !!! love you xxxxx You always say that my messages on here are too short so i'm making an effort to write you a longgggggggggggggggggg one this time hahaha happy birthday to you, happy birthday to you, happy birthday Khaleesy, Happy Birthday too youuuuuuuuuuuuuu....uuuuuuuu xxxxx | P14: 4 | Q14: 4 | R14: 2 | S14: 4 | T14: 4 | U14: 5 | V14: 4 | W14: 3 | X14: 4 | Y14: 4 | Z14: 3 | AA14: 3 | AB14: 4 | AC14: 3 | AD14: 1 | AE14: 3 | AF14: 3 | AG14: 3 | AH14: 3 | AI14: 2 | AJ14: 2 | AK14: 4 | AL14: 3 | AM14: 3 | AN14: 3 | AO14: 3 | AP14: 3 | AQ14: 3 | AR14: 1 | AS14: 4 | AT14: 3 | AU14: 4 | AV14: 3 | AW14: 2 | AX14: 4 | AY14: 3 | AZ14: 4 | BA14: 4 | BB14: 4 | BC14: 4 | BD14: 2 | BE14: 4 | BF14: 4 | BG14: 4 | BH14: 3 | BI14: 3 | BJ14: 4 | BK14: 4 | BL14: 3 | BM14: 4 | BN14: 3 | BO14: 4 | BP14: 2 | BQ14: 4 | BR14: 3 | BS14: 3 | BT14: 2 | BU14: 3 | BV14: 4 | BW14: 3 | BX14: 66c46c4e8a82f52621c06c4f | BZ14: other | CA14: Neutral | CB14: 0 | CC14: High | CD14: Love | CF14: 0 | CG14: 2 | CH14: Very Positive | CK14: Unknown | CL14: 1 | CM14: QID80,QID84
... A90: 665abb661d3f242a05ffb7ed | B90: ="p"&ROW(A88) -> p88 | C90: 45940.706 | D90: 45940.712 | E90: 163.120.92.137 | F90: 100 | G90: 494 | H90: True | I90: 45940.712 | J90: R_8nux4aP0Edj3FvK | K90: 51.5081 | L90: -0.1278 | M90: anonymous | N90: I attended a get together tonight where several of my childhood friends were there. It felt kind of weird as I never kept in touch with anyone after school (well except for one friend as we ended up working at the same place for a few months many years ago). I'm not sure why I went though as I much prefer being at home. | O90: Happy birthday to the love of my life. Let's have a fantastic few days away together to celebrate your birthday. It will be a lot of fun and a great chance to unwind as well. I hope you enjoy every bit of it and hope you get lots of wonderful gifts as well. It is always the best to see you smile. | P90: 4 | Q90: 3 | R90: 5 | S90: 5 | T90: 4 | U90: 5 | V90: 3 | W90: 4 | X90: 3 | Y90: 4 | Z90: 1 | AA90: 3 | AB90: 3 | AC90: 5 | AD90: 1 | AE90: 5 | AF90: 3 | AG90: 3 | AH90: 5 | AI90: 2 | AJ90: 2 | AK90: 3 | AL90: 2 | AM90: 5 | AN90: 2 | AO90: 3 | AP90: 5 | AQ90: 3 | AR90: 3 | AS90: 3 | AT90: 4 | AU90: 5 | AV90: 3 | AW90: 3 | AX90: 3 | AY90: 4 | AZ90: 3 | BA90: 2 | BB90: 2 | BC90: 2 | BD90: 2 | BE90: 3 | BF90: 4 | BG90: 3 | BH90: 5 | BI90: 3 | BJ90: 3 | BK90: 3 | BL90: 4 | BM90: 4 | BN90: 3 | BO90: 4 | BP90: 3 | BQ90: 3 | BR90: 5 | BS90: 3 | BT90: 3 | BU90: 3 | BV90: 3 | BW90: 5 | BX90: 665abb661d3f242a05ffb7ed | BZ90: other | CA90: Neutral | CB90: 0 | CC90: High | CD90: Love | CF90: 0 | CG90: 2 | CH90: Very Positive | CK90: Unknown | CL90: 1 | CM90: QID84
A91: 675ce427f72ea526d6083376 | B91: ="p"&ROW(A89) -> p89 | C91: 45940.706 | D91: 45940.72 | E91: 149.52.123.24 | F91: 100 | G91: 1169 | H91: True | I91: 45940.72 | J91: R_7Sf1JD8CHjeKZjP | K91: 37.751 | L91: -97.822 | M91: anonymous | N91: What a nolstalgic moment with childhood friends! We shared laughter, old school stories, silly games and the silly jokes we made back then. Talk of the punishments we received from parents and teachers back then, waah! We dint even realize the passage of time. I am grateful to have friends that have stood the test of time #Good friends with great vibes | O91: On this very special day, I cant hide my joy in celebrating my personal person who is the apple of my eyes. She is not only beautiful and elegant on the outside, but comes as a package with a warm, kind and loving heart. I thank the universe for making out paths cross that I got to meet her. She is an amazing person that I would love to spend my whole life with. I wish you my dear one a memorable day and good joyful days full of happiness all your days. Happy plus one birthday, to many more. | P91: 4 | Q91: 4 | R91: 1 | S91: 4 | T91: 3 | U91: 5 | V91: 4 | W91: 2 | X91: 3 | Y91: 4 | Z91: 5 | AA91: 4 | AB91: 3 | AC91: 2 | AD91: 3 | AE91: 3 | AF91: 1 | AG91: 2 | AH91: 1 | AI91: 3 | AJ91: 1 | AK91: 4 | AL91: 2 | AM91: 2 | AN91: 4 | AO91: 3 | AP91: 4 | AQ91: 5 | AR91: 1 | AS91: 4 | AT91: 1 | AU91: 2 | AV91: 1 | AW91: 2 | AX91: 3 | AY91: 1 | AZ91: 5 | BA91: 4 | BB91: 3 | BC91: 5 | BD91: 1 | BE91: 5 | BF91: 5 | BG91: 3 | BH91: 4 | BI91: 1 | BJ91: 3 | BK91: 4 | BL91: 5 | BM91: 4 | BN91: 1 | BO91: 3 | BP91: 3 | BQ91: 3 | BR91: 5 | BS91: 3 | BT91: 1 | BU91: 2 | BV91: 5 | BW91: 5 | BX91: 675ce427f72ea526d6083376 | BZ91: other | CA91: Neutral | CB91: 0 | CC91: High | CD91: Joy,Love | CF91: 0 | CG91: 2 | CH91: Very Positive | CK91: Unknown | CL91: 0
A92: 67327e4495f88dfc99471984 | B92: ="p"&ROW(A90) -> p90 | C92: 45940.706 | D92: 45940.716 | E92: 172.124.168.232 | F92: 100 | G92: 824 | H92: True | I92: 45940.716 | J92: R_5DJ11ZfKRBdmbf3 | K92: 29.8323 | L92: -95.736 | M92: anonymous | N92: Last night was the much-needed chaos I didn't know I needed! 🍻 Nothing beats a few hours with the crew that knew you when cargo pants were cool and before we had to worry about 401ks. We should definitely implement mandatory quarterly nostalgia sessions. Thanks for the laughs and the reminders of simpler times, guys! Now back to adulting... until next time! 🚀 | O92: Happy Birthday to my favorite partner in saving, traveling, and goal-crushing! 🎉 Every year with you feels like compounding interest—the returns just keep getting better. Thank you for your endless support, your sharp wit, and making the future look so bright. Wishing you a day as amazing as the positive net worth you bring to my life. I love you! ❤️ | P92: 4 | Q92: 5 | R92: 3 | S92: 1 | T92: 1 | U92: 4 | V92: 1 | W92: 4 | X92: 5 | Y92: 3 | Z92: 3 | AA92: 4 | AB92: 4 | AC92: 1 | AD92: 1 | AE92: 2 | AF92: 1 | AG92: 1 | AH92: 1 | AI92: 2 | AJ92: 1 | AK92: 1 | AL92: 3 | AM92: 3 | AN92: 4 | AO92: 1 | AP92: 5 | AQ92: 1 | AR92: 3 | AS92: 4 | AT92: 2 | AU92: 1 | AV92: 1 | AW92: 1 | AX92: 4 | AY92: 2 | AZ92: 3 | BA92: 4 | BB92: 4 | BC92: 4 | BD92: 4 | BE92: 4 | BF92: 4 | BG92: 2 | BH92: 1 | BI92: 4 | BJ92: 3 | BK92: 2 | BL92: 4 | BM92: 5 | BN92: 2 | BO92: 4 | BP92: 4 | BQ92: 3 | BR92: 2 | BS92: 1 | BT92: 4 | BU92: 1 | BV92: 3 | BW92: 4 | BX92: 67327e4495f88dfc99471984 | BZ92: other | CA92: Neutral | CB92: 0 | CC92: High | CD92: Love | CF92: 0 | CG92: 2 | CH92: Very Positive | CK92: Unknown | CL92: 1 | CM92: QID84
A93: 671b67f55fca5f2c8617fc2e | B93: ="p"&ROW(A91) -> p91 | C93: 45940.706 | D93: 45940.712 | E93: 216.120.189.178 | F93: 100 | G93: 492 | H93: True | I93: 45940.712 | J93: R_2KHF9xuldGCi5ZC | K93: 51.5081 | L93: -0.1278 | M93: anonymous | N93: outside with my boys have the fun of our life noting beat a childhood friend party. i am so happy i have my boys with me again From trading snacks at lunch to trading life updates now it’s wild to see how far we’ve all come, and yet how easily we fall back into rhythm. Same teasing, same warmth, just a little more grown up Grateful for the memories, the people who helped shape me, and the reminder that some roots run deep no matter how much time passes | O93: It’s your birthday and that means it’s time for cake, hugs, and a LOT of smiles!! You are my FAVORITE person and I’m super duper happy you were born You make me laugh a lot, you give the best hugs, and you're SO cool even cooler than superheroes I hope you get all the fun things today and forever I love you THIS MUCH | P93: 4 | Q93: 4 | R93: 2 | S93: 4 | T93: 5 | U93: 3 | V93: 3 | W93: 4 | X93: 4 | Y93: 3 | Z93: 3 | AA93: 3 | AB93: 4 | AC93: 4 | AD93: 3 | AE93: 3 | AF93: 3 | AG93: 4 | AH93: 4 | AI93: 3 | AJ93: 3 | AK93: 3 | AL93: 2 | AM93: 3 | AN93: 4 | AO93: 4 | AP93: 5 | AQ93: 4 | AR93: 2 | AS93: 5 | AT93: 3 | AU93: 3 | AV93: 1 | AW93: 2 | AX93: 2 | AY93: 2 | AZ93: 5 | BA93: 5 | BB93: 2 | BC93: 3 | BD93: 1 | BE93: 2 | BF93: 5 | BG93: 1 | BH93: 5 | BI93: 2 | BJ93: 4 | BK93: 5 | BL93: 5 | BM93: 5 | BN93: 4 | BO93: 5 | BP93: 4 | BQ93: 4 | BR93: 3 | BS93: 4 | BT93: 4 | BU93: 3 | BV93: 3 | BW93: 4 | BX93: 671b67f55fca5f2c8617fc2e | BZ93: other | CA93: Neutral | CB93: 0 | CC93: High | CD93: Love,Joy | CF93: 0 | CG93: 2 | CH93: Very Positive | CK93: Unknown | CL93: 1 | CM93: QID84
A94: 6744d143eddffd17d345b192 | B94: ="p"&ROW(A92) -> p92 | C94: 45940.707 | D94: 45940.712 | E94: 86.182.166.23 | F94: 100 | G94: 496 | H94: True | I94: 45940.712 | J94: R_8EEI07Rma1u0Dk8 | K94: 53.5005 | L94: -1.4832 | M94: anonymous | N94: Another one for the ages! Had an absolutely incredible time seeing my day 1 besties. My fondest memories are without a doubt with this gang and we have just created infinitely more memories in one night. Love all of yous that could attend and those who wanted to but couldn't &lt;3 20 years down let's make it another 60. | O94: I am nothing without this woman. She has changed everything about me in any way imaginable. The smartest, kindest, most intelligent, downright hilarious beautiful woman I have ever met and will ever meet in this life or the next. You are more than my wife Marina, you are the glue that holds my soul together. Without you I am merely a full person. Happy 27th birthday my love &lt;3 | P94: 5 | Q94: 5 | R94: 4 | S94: 5 | T94: 3 | U94: 5 | V94: 3 | W94: 4 | X94: 3 | Y94: 5 | Z94: 2 | AA94: 4 | AB94: 3 | AC94: 5 | AD94: 1 | AE94: 4 | AF94: 3 | AG94: 3 | AH94: 4 | AI94: 2 | AJ94: 1 | AK94: 4 | AL94: 3 | AM94: 4 | AN94: 2 | AO94: 1 | AP94: 5 | AQ94: 2 | AR94: 3 | AS94: 5 | AT94: 2 | AU94: 3 | AV94: 3 | AW94: 3 | AX94: 4 | AY94: 4 | AZ94: 5 | BA94: 2 | BB94: 3 | BC94: 4 | BD94: 2 | BE94: 5 | BF94: 2 | BG94: 3 | BH94: 4 | BI94: 5 | BJ94: 4 | BK94: 4 | BL94: 2 | BM94: 5 | BN94: 3 | BO94: 4 | BP94: 1 | BQ94: 2 | BR94: 2 | BS94: 1 | BT94: 1 | BU94: 2 | BV94: 5 | BW94: 2 | BX94: 6744d143eddffd17d345b192 | BZ94: other | CA94: Easy | CB94: 1 | CC94: High | CD94: Joy | CF94: 0 | CG94: 2 | CH94: Very Positive | CK94: Unknown | CL94: 1 | CM94: QID84
A95: 668e8b2d29cef7917c9b19bd | B95: ="p"&ROW(A93) -> p93 | C95: 45940.707 | D95: 45940.717 | E95: 86.24.53.172 | F95: 100 | G95: 895 | H95: True | I95: 45940.717 | J95: R_8Ctu80qMU3BTvZn | K95: 52.6667 | L95: 0.1667 | M95: anonymous | N95: Some friendships last forever! I'm so glad to have these people in my life since childhood, we had a great time and I want to thank everybody for being there! I hope to see you all very soon for our next meeting to share more laughs, drinks and silliness! Thanks again to be in my life! | O95: Happy birthday to the most important person in my life (after my cats obviously ah ah!) I hope you have great fun celebrating and I'm glad to celebrate with you! I love you and I hope to share with you many birthdays and beautiful moments like today! Thanks to be in my life, I love you so much! | P95: 5 | Q95: 5 | R95: 3 | S95: 4 | T95: 4 | U95: 5 | V95: 5 | W95: 3 | X95: 4 | Y95: 5 | Z95: 4 | AA95: 5 | AB95: 5 | AC95: 3 | AD95: 1 | AE95: 3 | AF95: 2 | AG95: 2 | AH95: 3 | AI95: 2 | AJ95: 1 | AK95: 5 | AL95: 2 | AM95: 2 | AN95: 4 | AO95: 1 | AP95: 5 | AQ95: 2 | AR95: 2 | AS95: 4 | AT95: 2 | AU95: 5 | AV95: 1 | AW95: 3 | AX95: 3 | AY95: 2 | AZ95: 5 | BA95: 5 | BB95: 5 | BC95: 4 | BD95: 2 | BE95: 5 | BF95: 5 | BG95: 5 | BH95: 3 | BI95: 4 | BJ95: 5 | BK95: 5 | BL95: 3 | BM95: 5 | BN95: 3 | BO95: 2 | BP95: 1 | BQ95: 5 | BR95: 4 | BS95: 1 | BT95: 1 | BU95: 1 | BV95: 5 | BW95: 5 | BX95: 668e8b2d29cef7917c9b19bd | BZ95: other | CA95: Neutral | CB95: 0 | CC95: High | CD95: Love | CF95: 0 | CG95: 2 | CH95: Very Positive | CK95: Unknown | CL95: 1 | CM95: QID84
A96: 67ca1243e7c4d398474fc95d | B96: ="p"&ROW(A94) -> p94 | C96: 45940.707 | D96: 45940.715 | E96: 90.247.35.6 | F96: 100 | G96: 712 | H96: True | I96: 45940.715 | J96: R_2OOprA2hkDYAlVf | K96: 52.5026 | L96: -1.7815 | M96: anonymous | N96: Last night was unreal, got together with childhood friends and ended up reminiscing, playing silly games, and sharing dumb jokes. It felt just like those summer evenings growing up. Grateful for everyone who showed up and made it wild. Honestly, these moments make life sweet. Can't wait for the next one! | O96: Happy birthday to the one who makes life brighter and better every single day. Thank you for laughing with me, supporting me, and just being yourself. I can't wait to make more memories together. Hope today is full of love, cake, and everything you adore. You truly deserve it all! | P96: 5 | Q96: 5 | R96: 3 | S96: 1 | T96: 5 | U96: 5 | V96: 5 | W96: 1 | X96: 4 | Y96: 5 | Z96: 5 | AA96: 5 | AB96: 5 | AC96: 2 | AD96: 2 | AE96: 1 | AF96: 1 | AG96: 1 | AH96: 1 | AI96: 1 | AJ96: 1 | AK96: 1 | AL96: 1 | AM96: 1 | AN96: 5 | AO96: 1 | AP96: 5 | AQ96: 5 | AR96: 2 | AS96: 5 | AT96: 1 | AU96: 5 | AV96: 1 | AW96: 5 | AX96: 5 | AY96: 1 | AZ96: 5 | BA96: 5 | BB96: 5 | BC96: 5 | BD96: 1 | BE96: 5 | BF96: 5 | BG96: 3 | BH96: 5 | BI96: 1 | BJ96: 5 | BK96: 5 | BL96: 5 | BM96: 5 | BN96: 1 | BO96: 2 | BP96: 3 | BQ96: 5 | BR96: 5 | BS96: 1 | BT96: 1 | BU96: 1 | BV96: 5 | BW96: 5 | BX96: 67ca1243e7c4d398474fc95d | BZ96: other | CA96: Neutral | CB96: 0 | CC96: High | CD96: Love | CF96: 0 | CG96: 2 | CH96: Very Positive | CK96: Unknown | CL96: 1 | CM96: QID84
A97: 67d43f5c7253c147df75e9e5 | B97: ="p"&ROW(A95) -> p95 | C97: 45940.707 | D97: 45940.722 | E97: 92.40.111.84 | F97: 100 | G97: 1236 | H97: True | I97: 45940.722 | J97: R_25GaB5H6nFPh9uc | K97: 51.9142 | L97: -0.3716 | M97: anonymous | N97: This is the type of friendship that can withstand long distance separation! Even though we have been separated for some time, it feels like we were together just the other day. Our childhood memories are still fresh as if it has not been over a two decades now. My heart if full, we have been laughing about some funny events that occurred when we were growing up. We ended up talking about our early days instead of our present lives.. #Reunion #Childhoodmemories | O97: What a wonderful day! I thank the heavens for this wonderful being. Congratulations on your birthday. May you have all the desires of your heart. May your days be filled with good health and joy. I love you! Happy Happy birthday. Cheers to many more years years as we create memories together. | P97: 5 | Q97: 4 | R97: 2 | S97: 3 | T97: 4 | U97: 5 | V97: 5 | W97: 2 | X97: 4 | Y97: 5 | Z97: 4 | AA97: 5 | AB97: 4 | AC97: 2 | AD97: 1 | AE97: 1 | AF97: 1 | AG97: 1 | AH97: 1 | AI97: 2 | AJ97: 1 | AK97: 3 | AL97: 2 | AM97: 2 | AN97: 5 | AO97: 1 | AP97: 5 | AQ97: 5 | AR97: 2 | AS97: 5 | AT97: 1 | AU97: 4 | AV97: 1 | AW97: 3 | AX97: 4 | AY97: 2 | AZ97: 5 | BA97: 5 | BB97: 5 | BC97: 5 | BD97: 1 | BE97: 5 | BF97: 5 | BG97: 3 | BH97: 5 | BI97: 1 | BJ97: 4 | BK97: 4 | BL97: 5 | BM97: 5 | BN97: 1 | BO97: 3 | BP97: 1 | BQ97: 4 | BR97: 4 | BS97: 1 | BT97: 1 | BU97: 3 | BV97: 5 | BW97: 5 | BX97: 67d43f5c7253c147df75e9e5 | BZ97: other | CA97: Neutral | CB97: 0 | CC97: High | CD97: Love | CF97: 0 | CG97: 2 | CH97: Very Positive | CK97: Unknown | CL97: 1 | CM97: QID84
A98: 67811c4fdaa9119f0fe31fca | B98: ="p"&ROW(A96) -> p96 | C98: 45940.708 | D98: 45940.713 | E98: 31.49.117.140 | F98: 100 | G98: 450 | H98: True | I98: 45940.713 | J98: R_8St62y47Bbouhup | K98: 52.547 | L98: -1.9396 | M98: anonymous | N98: Just wanted to say guys, it was amazing to see you all. Although we are all older we are definitely not wiser. My head hurts so much after all those shots of tequila and Barry you haven’t changed. Still being sick in the corner. We must do this more regularly. Let’s not leave it another 35 years as my liver won’t be able to cope. | O98: To my love and my best friend. Here’s to another year together. I hope I’m with you for the next 40 years. Here’s to sucking digestives together in the old people home. I love you every day. Even though you irritate the shit out of me sometimes. I couldn’t be without you. Happy birthday hunny. All my love xxx xxx | P98: 4 | Q98: 5 | R98: 4 | S98: 5 | T98: 5 | U98: 3 | V98: 3 | W98: 1 | X98: 2 | Y98: 5 | Z98: 3 | AA98: 4 | AB98: 3 | AC98: 5 | AD98: 1 | AE98: 1 | AF98: 1 | AG98: 2 | AH98: 1 | AI98: 5 | AJ98: 1 | AK98: 5 | AL98: 3 | AM98: 2 | AN98: 5 | AO98: 1 | AP98: 3 | AQ98: 5 | AR98: 2 | AS98: 5 | AT98: 2 | AU98: 5 | AV98: 1 | AW98: 2 | AX98: 4 | AY98: 3 | AZ98: 5 | BA98: 5 | BB98: 4 | BC98: 4 | BD98: 2 | BE98: 5 | BF98: 5 | BG98: 2 | BH98: 5 | BI98: 1 | BJ98: 2 | BK98: 5 | BL98: 4 | BM98: 5 | BN98: 1 | BO98: 2 | BP98: 1 | BQ98: 2 | BR98: 5 | BS98: 1 | BT98: 1 | BU98: 2 | BV98: 5 | BW98: 5 | BX98: 67811c4fdaa9119f0fe31fca | BZ98: other | CA98: Neutral | CB98: 0 | CC98: High | CD98: Mixed | CF98: 0 | CG98: 2 | CH98: Very Positive | CK98: Unknown | CL98: 1 | CM98: QID84
A99: 66959cf50e37b3130e0aeab4 | B99: ="p"&ROW(A97) -> p97 | C99: 45940.708 | D99: 45940.723 | E99: 84.69.53.211 | F99: 100 | G99: 1222 | H99: True | I99: 45940.723 | J99: R_8K137KvaJAaYnTa | K99: 50.8331 | L99: -1.2341 | M99: anonymous | N99: Catching up with my long time friends and paddies is something that money can't quantify. It is a moment I cherish every single bit of it. It was lit as expected and I can't let go. lots of discussion about the past that I wished time stood still and never moved an each. We also discussed about the realities of life in recent times. It was worth the time spent. | O99: Happy birthday to you my dearest friend. On you special day I just want to wish you love and happiness. I cherish every moment we spend together, the way you way smile every now and then always captivate me. I can't forget your angelic voice especially when you sing, It sounds so heavenly. Please accept my warmest wishes. | P99: 4 | Q99: 3 | R99: 2 | S99: 2 | T99: 3 | U99: 4 | V99: 3 | W99: 1 | X99: 2 | Y99: 3 | Z99: 4 | AA99: 4 | AB99: 3 | AC99: 3 | AD99: 1 | AE99: 2 | AF99: 2 | AG99: 3 | AH99: 2 | AI99: 4 | AJ99: 3 | AK99: 2 | AL99: 3 | AM99: 2 | AN99: 4 | AO99: 3 | AP99: 4 | AQ99: 3 | AR99: 2 | AS99: 3 | AT99: 2 | AU99: 5 | AV99: 2 | AW99: 4 | AX99: 3 | AY99: 3 | AZ99: 3 | BA99: 3 | BB99: 3 | BC99: 3 | BD99: 2 | BE99: 4 | BF99: 3 | BG99: 2 | BH99: 3 | BI99: 2 | BJ99: 3 | BK99: 3 | BL99: 3 | BM99: 4 | BN99: 3 | BO99: 4 | BP99: 3 | BQ99: 2 | BR99: 3 | BS99: 2 | BT99: 3 | BU99: 3 | BV99: 4 | BW99: 4 | BX99: 66959cf50e37b3130e0aeab4 | BZ99: other | CA99: Neutral | CB99: 0 | CC99: Medium | CD99: Joy,Love | CF99: 0 | CG99: 2 | CH99: Very Positive | CK99: Unknown | CL99: 1 | CM99: QID84
A100: 5f517edd007af03cbf15085f | B100: ="p"&ROW(A98) -> p98 | C100: 45940.711 | D100: 45940.716 | E100: 73.223.229.220 | F100: 100 | G100: 443 | H100: True | I100: 45940.716 | J100: R_3EWQkgZD57p4VL5 | K100: 37.6736 | L100: -122.0944 | M100: anonymous | N100: I went out and hung out with a few of my childhood friends today. It was awesome and the way it all came together was crazy. Basically I was out shopping and I ran into one of them who I had not seen in 5 years. After chatting a bit he told me about how he had actually reunited with the other 2 recently and they all moved back to the city. After finding this out we quickly made a group chat and began to catchup and reminisce about the old days. | O100: Happy Birthday to the greatest partner ever. Today is more than just a simple celebration, but rather a monumental day of happiness and love. I know I speak for everyone when I say that you are a huge and integral part of my life and I could not ever picture an existence without you in it. I am so grateful to be with you and be able to call you my partner. Happy Birthday! | P100: 5 | Q100: 5 | R100: 1 | S100: 4 | T100: 3 | U100: 4 | V100: 5 | W100: 2 | X100: 2 | Y100: 5 | Z100: 4 | AA100: 4 | AB100: 4 | AC100: 3 | AD100: 1 | AE100: 1 | AF100: 2 | AG100: 3 | AH100: 2 | AI100: 4 | AJ100: 1 | AK100: 3 | AL100: 2 | AM100: 2 | AN100: 4 | AO100: 1 | AP100: 4 | AQ100: 3 | AR100: 2 | AS100: 4 | AT100: 1 | AU100: 3 | AV100: 1 | AW100: 3 | AX100: 3 | AY100: 2 | AZ100: 4 | BA100: 3 | BB100: 3 | BC100: 3 | BD100: 1 | BE100: 4 | BF100: 4 | BG100: 3 | BH100: 4 | BI100: 1 | BJ100: 3 | BK100: 3 | BL100: 3 | BM100: 3 | BN100: 1 | BO100: 3 | BP100: 1 | BQ100: 5 | BR100: 4 | BS100: 2 | BT100: 1 | BU100: 3 | BV100: 3 | BW100: 3 | BX100: 5f517edd007af03cbf15085f | BZ100: other | CA100: Neutral | CB100: 0 | CC100: High | CD100: Joy,Love,Thankfulness | CF100: 0 | CG100: 2 | CH100: Very Positive | CK100: Unknown | CL100: 1 | CM100: QID84
A101: 665daf967d49ecde0b65ec09 | B101: ="p"&ROW(A99) -> p99 | C101: 45940.713 | D101: 45940.718 | E101: 81.154.6.33 | F101: 100 | G101: 432 | H101: True | I101: 45940.718 | J101: R_8yjpPdBYpTxQOFb | K101: 51.4746 | L101: -0.2517 | M101: anonymous | N101: Always fun sharing great memories of past adventures with these friends. People often take for granted the value of longstanding friendships and relationships. Looking forward to more exciting times to come with this crew! Thank you guys for always being there through good times and bad. | O101: Happy Birthday to my beautiful girlfriend. A special day to celebrate you and all that you are - please never change! I honestly can't imagine what my life would be like without you in it and I truly hope I will never have to face that day. Thank you for everything that you do and I wish you a day filled with happiness. | P101: 4 | Q101: 3 | R101: 4 | S101: 3 | T101: 5 | U101: 2 | V101: 4 | W101: 1 | X101: 4 | Y101: 5 | Z101: 4 | AA101: 2 | AB101: 5 | AC101: 1 | AD101: 2 | AE101: 1 | AF101: 1 | AG101: 2 | AH101: 1 | AI101: 5 | AJ101: 2 | AK101: 4 | AL101: 1 | AM101: 1 | AN101: 5 | AO101: 1 | AP101: 4 | AQ101: 4 | AR101: 3 | AS101: 2 | AT101: 1 | AU101: 5 | AV101: 1 | AW101: 2 | AX101: 2 | AY101: 1 | AZ101: 3 | BA101: 5 | BB101: 5 | BC101: 4 | BD101: 3 | BE101: 2 | BF101: 5 | BG101: 4 | BH101: 4 | BI101: 1 | BJ101: 4 | BK101: 3 | BL101: 3 | BM101: 5 | BN101: 1 | BO101: 3 | BP101: 4 | BQ101: 5 | BR101: 5 | BS101: 1 | BT101: 3 | BU101: 3 | BV101: 5 | BW101: 5 | BX101: 665daf967d49ecde0b65ec09 | BZ101: other | CA101: Neutral | CB101: 0 | CC101: Low | CD101: Mixed | CF101: 0 | CG101: 2 | CH101: Very Positive | CK101: Unknown | CL101: 1 | CM101: QID84
A102: 60f154e3b41e8202276ccc73 | B102: ="p"&ROW(A100) -> p100 | C102: 45940.713 | D102: 45940.721 | E102: 145.224.65.196 | F102: 100 | G102: 615 | H102: True | I102: 45940.721 | J102: R_2JIA1KXk1crTh5u | K102: 51.5081 | L102: -0.1278 | M102: anonymous | N102: These girls never fail to disappoint!! No matter how long we go without speaking, it's like we've never spent a day apart! 🤪 Always so good to catch up, lets not leave it so long next time eh?! We have so many memories, some we'd rather forget but ultimately they have made our friendship stronger throughout the years, from the school days, to the early twenties shenanigans to now and would you just look at us!! Love you all, these are the days of our lives! ♥️ | O102: A big happy birthday to my little 🚀 You are such a strong woman, I've never known anyone like you and I can't wait to spend the rest of our lives together. Me and you against the world darling ♥️ Have the best day ever, hope you enjoy it and love all your pressies. Love you ALWAYS xxxxx | P102: 4 | Q102: 2 | R102: 3 | S102: 5 | T102: 5 | U102: 2 | V102: 4 | W102: 1 | X102: 3 | Y102: 5 | Z102: 5 | AA102: 3 | AB102: 5 | AC102: 4 | AD102: 1 | AE102: 3 | AF102: 1 | AG102: 2 | AH102: 1 | AI102: 4 | AJ102: 4 | AK102: 5 | AL102: 5 | AM102: 2 | AN102: 4 | AO102: 2 | AP102: 5 | AQ102: 5 | AR102: 3 | AS102: 5 | AT102: 2 | AU102: 4 | AV102: 1 | AW102: 3 | AX102: 3 | AY102: 3 | AZ102: 1 | BA102: 2 | BB102: 3 | BC102: 2 | BD102: 2 | BE102: 2 | BF102: 5 | BG102: 3 | BH102: 4 | BI102: 5 | BJ102: 4 | BK102: 3 | BL102: 4 | BM102: 4 | BN102: 1 | BO102: 4 | BP102: 2 | BQ102: 2 | BR102: 1 | BS102: 4 | BT102: 3 | BU102: 2 | BV102: 4 | BW102: 5 | BX102: 60f154e3b41e8202276ccc73 | BZ102: other | CA102: Neutral | CB102: 0 | CC102: High | CD102: Joy,Love | CF102: 0 | CG102: 2 | CH102: Very Positive | CK102: Unknown | CL102: 1 | CM102: QID84
A103: 637f7c5ecaecb61bc8722a35 | B103: ="p"&ROW(A101) -> p101 | C103: 45941.501 | D103: 45941.508 | E103: 86.159.215.30 | F103: 100 | G103: 629 | H103: True | I103: 45941.508 | J103: R_26lNHaSM5AiaL6c | K103: 51.5164 | L103: -0.093 | M103: anonymous | N103: Having such a good weekend for our annual uni meetup! Makes you realise you need to keep in contact more than just once a year! xD I am so glad to have met these people and we may not see eachother much but when we do we just slot back together, it's like no time has gone at all! Love you all :D | O103: Happy Birthday Rachel! I am so glad you came into my life and I couldn't ask for a better partner. I am so proud of the progress you are making every day and I can't wait to celebrate this and many more birthdays with you! Thank you for being you! Lots of love, Chris xxxxxxxxxx | P103: 5 | Q103: 3 | R103: 3 | S103: 4 | T103: 2 | U103: 5 | V103: 4 | W103: 3 | X103: 4 | Y103: 4 | Z103: 1 | AA103: 4 | AB103: 5 | AC103: 5 | AD103: 1 | AE103: 4 | AF103: 2 | AG103: 3 | AH103: 3 | AI103: 4 | AJ103: 3 | AK103: 4 | AL103: 5 | AM103: 3 | AN103: 4 | AO103: 5 | AP103: 3 | AQ103: 2 | AR103: 1 | AS103: 4 | AT103: 2 | AU103: 2 | AV103: 5 | AW103: 2 | AX103: 4 | AY103: 4 | AZ103: 5 | BA103: 3 | BB103: 5 | BC103: 3 | BD103: 2 | BE103: 5 | BF103: 2 | BG103: 4 | BH103: 3 | BI103: 2 | BJ103: 3 | BK103: 2 | BL103: 3 | BM103: 3 | BN103: 2 | BO103: 4 | BP103: 1 | BQ103: 5 | BR103: 2 | BS103: 3 | BT103: 2 | BU103: 2 | BV103: 4 | BW103: 4 | BX103: 637f7c5ecaecb61bc8722a35 | BZ103: other | CA103: Easy | CB103: 1 | CC103: High | CD103: Love,Joy | CF103: 0 | CG103: 2 | CH103: Very Positive | CK103: Unknown | CL103: 1 | CM103: QID84
... A107: 67a95d468d14bd6324b4bbba | B107: ="p"&ROW(A105) -> p105 | C107: 45941.501 | D107: 45941.509 | E107: 113.20.53.210 | F107: 100 | G107: 684 | H107: True | I107: 45941.509 | J107: R_6cdVKvj5MmQRaBc | K107: 39.0814 | L107: -77.6443 | M107: anonymous | N107: Just got back from an amazing evening with my childhood friends! We laughed until our stomachs hurt, shared stories from the past, and caught up on everything happening in our lives now. Nights like this remind me how lucky I am to have friends who feel like family, no matter the years between us. | O107: Happy Birthday to the most incredible person in my life! You inspire me every single day with your kindness, humor, and endless love. I’m so grateful for every moment we share, for all the laughter, adventures, and memories we’ve created together. May your special day be filled with joy, love, happiness, and everything that makes your heart truly smile. You deserve all the amazing things life has to offer, today and always! | P107: 5 | Q107: 5 | R107: 1 | S107: 3 | T107: 4 | U107: 4 | V107: 4 | W107: 1 | X107: 1 | Y107: 5 | Z107: 5 | AA107: 5 | AB107: 5 | AC107: 5 | AD107: 1 | AE107: 1 | AF107: 1 | AG107: 3 | AH107: 1 | AI107: 1 | AJ107: 1 | AK107: 4 | AL107: 4 | AM107: 4 | AN107: 4 | AO107: 1 | AP107: 5 | AQ107: 5 | AR107: 2 | AS107: 5 | AT107: 2 | AU107: 2 | AV107: 1 | AW107: 5 | AX107: 5 | AY107: 1 | AZ107: 5 | BA107: 5 | BB107: 5 | BC107: 5 | BD107: 1 | BE107: 5 | BF107: 5 | BG107: 5 | BH107: 5 | BI107: 1 | BJ107: 5 | BK107: 5 | BL107: 5 | BM107: 5 | BN107: 1 | BO107: 4 | BP107: 5 | BQ107: 1 | BR107: 4 | BS107: 1 | BT107: 1 | BU107: 1 | BV107: 4 | BW107: 4 | BX107: 67a95d468d14bd6324b4bbba | BZ107: other | CA107: Neutral | CB107: 0 | CC107: High | CD107: Thankfulness,Joy,Love | CF107: 0 | CG107: 2 | CH107: Very Positive | CK107: Unknown | CL107: 1 | CM107: QID84
A108: 62b437a2dbff0b6b3d0121e4 | B108: ="p"&ROW(A106) -> p106 | D108: 46002.785 | E108: 86.180.124.255 | F108: 100 | G108: 343 | H108: TRUE | I108: 46002.785 | J108: R_8no74MoIgu9Zyog | N108: Catching up with my friends felt like being a time capsule tonight. We laughed about old stories, argued about who remembered them correctly and thought about how much things have and havenâ€™t changed. It was nice to see old familiar faces and reminisce on our shared history. Nights like this one remind me how lucky I am to have spent so much time with you growing up | O108: Happy Birthday to the person who makes the most dull days feel wonderful. Today reminds me how amazing you are and how lucky I am to share my life with someone who brings so much humour, warmth and love. Thankyou for everything, I hope this next year brings you everything you ask for. I love you | P108: 5 | Q108: 2 | R108: 3 | S108: 5 | T108: 5 | U108: 2 | V108: 5 | W108: 1 | X108: 4 | Y108: 5 | Z108: 5 | AA108: 5 | AB108: 4 | AC108: 3 | AD108: 1 | AE108: 4 | AF108: 1 | AG108: 1 | AH108: 3 | AI108: 5 | AJ108: 3 | AK108: 5 | AL108: 4 | AM108: 1 | AN108: 4 | AO108: 3 | AP108: 3 | AQ108: 2 | AR108: 1 | AS108: 4 | AT108: 1 | AU108: 5 | AV108: 2 | AW108: 1 | AX108: 2 | AY108: 4 | AZ108: 2 | BA108: 4 | BB108: 5 | BC108: 4 | BD108: 3 | BE108: 2 | BF108: 5 | BG108: 5 | BH108: 4 | BI108: 2 | BJ108: 5 | BK108: 2 | BL108: 4 | BM108: 4 | BN108: 2 | BO108: 2 | BP108: 1 | BQ108: 4 | BR108: 4 | BS108: 4 | BT108: 1 | BU108: 1 | BV108: 4 | BW108: 5 | BY108: other | BZ108: Neutral | CA108: 0 | CB108: High | CC108: Love | CF108: 0 | CG108: 2 | CH108: Very Positive | CK108: Unknown | CL108: 1 | CM108: QID84
A109: 67868bfd54b06784ec11ae1c | B109: ="p"&ROW(A107) -> p107 | D109: 46002.787 | E109: 51.14.78.88 | F109: 100 | G109: 411 | H109: TRUE | I109: 46002.787 | J109: R_81dpknKYE4Gt1zm | N109: what a great catch up with the best guys out there. havent seen some of them for what feels like years but the memories just came flooding back of all the good times and laughter we had. We went for Lunch then onto the cinema and finally rounded the day off with a few beers in the local, till next time. | O109: Happy Birthday to the best mum and wife out there and i know everyone says that but you truely are, you are always putting us before you and today just for once to quote mcfly its all about you, so put your feet up and let me and the kids take care of dinner and the washing up and you can relax for once | P109: 5 | Q109: 3 | R109: 4 | S109: 4 | T109: 3 | U109: 5 | V109: 4 | W109: 2 | X109: 4 | Y109: 4 | Z109: 3 | AA109: 5 | AB109: 5 | AC109: 4 | AD109: 3 | AE109: 2 | AF109: 2 | AG109: 3 | AH109: 2 | AI109: 4 | AJ109: 3 | AK109: 4 | AL109: 2 | AM109: 3 | AN109: 4 | AO109: 2 | AP109: 5 | AQ109: 4 | AR109: 2 | AS109: 4 | AT109: 3 | AU109: 4 | AV109: 2 | AW109: 4 | AX109: 4 | AY109: 3 | AZ109: 4 | BA109: 3 | BB109: 4 | BC109: 4 | BD109: 4 | BE109: 5 | BF109: 4 | BG109: 4 | BH109: 4 | BI109: 2 | BJ109: 5 | BK109: 2 | BL109: 4 | BM109: 5 | BN109: 2 | BO109: 3 | BP109: 3 | BQ109: 4 | BR109: 4 | BS109: 4 | BT109: 2 | BU109: 4 | BV109: 4 | BW109: 4 | BY109: other | BZ109: Neutral | CA109: 0 | CB109: Medium | CC109: Joy | CF109: 0 | CG109: 2 | CH109: Very Positive | CK109: Unknown | CL109: 1 | CM109: QID84
A110: 62c4d5821033848c1dc3667b | B110: ="p"&ROW(A108) -> p108 | D110: 46002.787 | E110: 162.251.59.205 | F110: 100 | G110: 489 | H110: TRUE | I110: 46002.787 | J110: R_7F4AN3tRwQ6qsvf | N110: Me and the guys finally found time in our busy adult lives to hang out and catch up with one another. We met at the ball field where we spent many days out there playing games. It was fun and very much needed to get out and feel like old times. Sometimes we get so busy with life and taking care of adult things that we forget how to be a kid but I think it is important that we have more of these days again to be youthful and regain a sense of happiness because those days we spent on the field truly were my happy days. | O110: Happy birthday to my beautiful wife. I am so thankful I get to share these special occasions with you and I hope I can make this day extra special just as you are. You do so much for me and often I may fail to do the same for you. Your birthday is a reminder that you are so special and deserve special treatment. I want to take you to dinner tonight and this weekend I want you to pick an outing that you want to do. Anything for you! I love you! | P110: 4 | Q110: 5 | R110: 3 | S110: 4 | T110: 4 | U110: 4 | V110: 3 | W110: 2 | X110: 1 | Y110: 4 | Z110: 3 | AA110: 3 | AB110: 3 | AC110: 3 | AD110: 1 | AE110: 1 | AF110: 1 | AG110: 3 | AH110: 1 | AI110: 5 | AJ110: 2 | AK110: 3 | AL110: 2 | AM110: 2 | AN110: 5 | AO110: 2 | AP110: 4 | AQ110: 4 | AR110: 2 | AS110: 4 | AT110: 2 | AU110: 3 | AV110: 2 | AW110: 3 | AX110: 4 | AY110: 2 | AZ110: 4 | BA110: 4 | BB110: 3 | BC110: 3 | BD110: 2 | BE110: 4 | BF110: 4 | BG110: 3 | BH110: 5 | BI110: 2 | BJ110: 2 | BK110: 1 | BL110: 3 | BM110: 4 | BN110: 2 | BO110: 5 | BP110: 1 | BQ110: 3 | BR110: 3 | BS110: 1 | BT110: 2 | BU110: 3 | BV110: 3 | BW110: 5 | BY110: other | BZ110: Neutral | CA110: 0 | CB110: High | CC110: Joy,Love | CF110: 0 | CG110: 2 | CH110: Very Positive | CK110: Unknown | CL110: 1 | CM110: QID84
A111: 67a96562e2b052e6c15ed963 | B111: ="p"&ROW(A109) -> p109 | D111: 46002.787 | E111: 92.40.204.102 | F111: 100 | G111: 407 | H111: TRUE | I111: 46002.787 | J111: R_8P3W0r8RYmwZ4Qh | N111: Glad to see everybody, can't believe that I used to be much younger and at school with all of these amazing people. Thank you so much for the great time, everybody was great to talk to and I really liked sharing our stories of how our lives have turned out. Best wishes to everyone and let's all meet up again in another 20 years. | O111: Happy birthday, glad I could share it with you and the friends and family we have together. I feel happy every day I have met you and I love you. Here's to another year of us together and all the memories we share. Lots of gifts and cake to go around and you managed to blow out all of the candles in one, good job. | P111: 4 | Q111: 5 | R111: 5 | S111: 2 | T111: 2 | U111: 5 | V111: 5 | W111: 4 | X111: 1 | Y111: 2 | Z111: 5 | AA111: 5 | AB111: 5 | AC111: 4 | AD111: 1 | AE111: 5 | AF111: 4 | AG111: 5 | AH111: 4 | AI111: 1 | AJ111: 1 | AK111: 5 | AL111: 4 | AM111: 5 | AN111: 4 | AO111: 5 | AP111: 3 | AQ111: 5 | AR111: 2 | AS111: 4 | AT111: 5 | AU111: 2 | AV111: 4 | AW111: 5 | AX111: 2 | AY111: 4 | AZ111: 5 | BA111: 5 | BB111: 5 | BC111: 3 | BD111: 4 | BE111: 5 | BF111: 4 | BG111: 5 | BH111: 3 | BI111: 4 | BJ111: 3 | BK111: 5 | BL111: 3 | BM111: 3 | BN111: 3 | BO111: 2 | BP111: 5 | BQ111: 3 | BR111: 4 | BS111: 1 | BT111: 2 | BU111: 3 | BV111: 2 | BW111: 5 | BY111: other | BZ111: Neutral | CA111: 0 | CB111: High | CC111: Love | CF111: 0 | CG111: 2 | CH111: Very Positive | CK111: Unknown | CL111: 1 | CM111: QID84
A112: 64fb3be137d2bd2bdfab8ba6 | B112: ="p"&ROW(A110) -> p110 | D112: 46002.788 | E112: 71.206.56.149 | F112: 100 | G112: 481 | H112: TRUE | I112: 46002.788 | J112: R_5cv1DOqyWKfyHWV | N112: I went to the racetrack and sat on the deck outside overlooking the finish line. I was with a boyhood friend. We sat down and another boyhood friend was sitting nearby. I went over and deliberately bumped into him and was surprised he did not immediately recognize me because he was vain and not wearing his eye glasses. In our ensuring talk, he turned out to be a "dick". | O112: I am so delighted to be able to share this milestone with you. Somehow we have gotten this far. Some credit goes to our genes, the rest, to moderation. Who would have thought that this event would be happening years ago, when the world was falling apart. It took heroic steps to get up and continue when all seemed lost. You did it. Congratulations. Go Moderation Go! | P112: 4 | Q112: 5 | R112: 2 | S112: 4 | T112: 3 | U112: 4 | V112: 4 | W112: 1 | X112: 1 | Y112: 3 | Z112: 5 | AA112: 3 | AB112: 3 | AC112: 2 | AD112: 1 | AE112: 1 | AF112: 1 | AG112: 3 | AH112: 2 | AI112: 4 | AJ112: 1 | AK112: 5 | AL112: 2 | AM112: 1 | AN112: 4 | AO112: 2 | AP112: 4 | AQ112: 4 | AR112: 3 | AS112: 4 | AT112: 1 | AU112: 4 | AV112: 1 | AW112: 4 | AX112: 3 | AY112: 1 | AZ112: 4 | BA112: 3 | BB112: 3 | BC112: 4 | BD112: 1 | BE112: 4 | BF112: 5 | BG112: 2 | BH112: 4 | BI112: 2 | BJ112: 3 | BK112: 5 | BL112: 3 | BM112: 4 | BN112: 1 | BO112: 4 | BP112: 2 | BQ112: 4 | BR112: 4 | BS112: 2 | BT112: 1 | BU112: 4 | BV112: 4 | BW112: 4 | BY112: other | BZ112: Neutral | CA112: 0 | CB112: High | CC112: Joy | CF112: 0 | CG112: 2 | CH112: Very Positive | CK112: Unknown | CL112: 1 | CM112: QID84
A113: 5f0f6811a0ed4a11dbc57b79 | B113: ="p"&ROW(A111) -> p111 | D113: 46002.788 | E113: 95.214.228.107 | F113: 100 | G113: 502 | H113: TRUE | I113: 46002.788 | J113: R_88NvMAZ9pma5CTE | N113: It was great seeing my childhood friends at the social gathering. I have not seen them for many years and it was nice opportunity to re-connect. Some have become grandparents at such a young age, its quite astonishing how time literally flies by. Many have moved to different locations in the UK and couple had moved abroad. Shame our school was knocked down. | O113: Happy birthday to my dear one, I hope you have fantastic day. As each year goes by you become more endearing to me and I cherish each moment I spend time with you. As you grow another year older, you have become more wiser and beautiful with time. May you have more birthday celebrations to come. | P113: 5 | Q113: 5 | R113: 2 | S113: 4 | T113: 5 | U113: 5 | V113: 5 | W113: 1 | X113: 2 | Y113: 5 | Z113: 5 | AA113: 5 | AB113: 5 | AC113: 2 | AD113: 1 | AE113: 1 | AF113: 1 | AG113: 2 | AH113: 1 | AI113: 4 | AJ113: 1 | AK113: 4 | AL113: 2 | AM113: 1 | AN113: 5 | AO113: 5 | AP113: 4 | AQ113: 5 | AR113: 2 | AS113: 5 | AT113: 1 | AU113: 4 | AV113: 1 | AW113: 3 | AX113: 5 | AY113: 1 | AZ113: 5 | BA113: 5 | BB113: 3 | BC113: 4 | BD113: 1 | BE113: 5 | BF113: 5 | BG113: 3 | BH113: 5 | BI113: 1 | BJ113: 3 | BK113: 5 | BL113: 5 | BM113: 5 | BN113: 1 | BO113: 5 | BP113: 4 | BQ113: 5 | BR113: 5 | BS113: 1 | BT113: 1 | BU113: 4 | BV113: 5 | BW113: 5 | BY113: other | BZ113: Neutral | CA113: 0 | CB113: Low | CC113: Joy | CF113: 0 | CG113: 2 | CH113: Very Positive | CK113: Unknown | CL113: 1 | CM113: QID84
